Workbook

Sheet List Project
A1: No | B1: ID Project | C1: Tahun | D1: Periode | E1: Nama Project | F1: Jenis Project | G1: PMG | H1: PM | I1: Revenue Akhir | J1: Segment Sales | K1: Klasifikasi Project | L1: Nama AM | M1: Tanggal Project Charter | N1: Target | O1: Nama PIC | P1: Status | Q1: Order | R1: Konfigurasi | S1: Integrasi | T1: Tshoot | U1: Keterangan | V1: PM
A2: 1 | B2: P232251-01-00 | C2: 2024 | D2: Januari | E2: Perpanjangan Layanan Omnichannel Untuk PT Inti Cakrawala Citra (Indogrosir) 2023-2025 | F2: CRM | G2: CRM 1 | H2: AGM | I2: 328800000 | J2: Private | K2: C | L2: Robby Kautsar | M2: 45266 | N2: 45294 | O2: Duta | P2: Done
A3: 2 | B3: P232385-03-00 | C3: 2024 | D3: Januari | E3: Layanan Contact Center Voice LKPP Desember 2023 | F3: CRM | G3: CRM 2 | H3: MIH | I3: 85100000 | J3: Telkom Group | K3: C | L3: Alldicka Christvelldy | M3: 45276 | N3: 45303 | O3: Duta | P3: Done
A4: 3 | B4: P232154-03-00 | C4: 2024 | D4: Januari | E4: Pengadaan Jasa Managed Operation Pengelolaan Contact BRI Site Jakarta | F4: CRM | G4: CRM 2 | H4: RGZ | I4: 9980698000 | J4: SOE | K4: A | L4: Artha | M4: 45293 | N4: 45317 | O4: Adi | P4: Done
A5: 4 | B5: P232417-01-00 | C5: 2024 | D5: Januari | E5: Nomor Akses 1500024 Universitas Terbuka | F5: Nomor Akses | G5: =SUM('List Project'!I:I) -> 2.1862641e+12 | H5: ARY | I5: 140460000 | J5: SOE | K5: C | L5: Ricka Winatha | M5: 45300 | N5: 45324 | O5: Dwi | P5: Done
A6: 5 | B6: P232472-02-00 | C6: 2024 | D6: Januari | E6: Nomor Akses 1500158 UNIVERSITAS GUNADARMA | F6: Nomor Akses | G6: CRM 1 | H6: PGP | I6: 88000000 | J6: Private | K6: C | L6: Fadel Bahruraji | M6: 45300 | N6: 45324 | O6: Duta | P6: Done
A7: 6 | B7: P232558-03-00 | C7: 2024 | D7: Januari | E7: Pengadaan Jasa Contact Center Pelayanan Publik pada Ditjen Kekayaan Intelektual-DKI Jakarta TA 2024 | F7: CRM | G7: CRM 2 | H7: MIH | I7: 5060900901 | J7: SME & GOV | K7: A | L7: Alldicka Christvelldy | M7: 45301 | N7: 45351 | O7: Duta | P7: Done
A8: 7 | B8: P232499-03-00 | C8: 2024 | D8: Januari | E8: Jasa Layanan Contact Center Kementerian Investasi (BKPM) Tahun 2024 | F8: CRM | G8: CRM 1 | H8: AGM | I8: 32506539688 | J8: SME & GOV | K8: A | L8: Akhmad Yani | M8: 45302 | N8: 45359 | O8: Duta | P8: Done
A9: 8 | B9: P232329-03-00 | C9: 2024 | D9: Januari | E9: Novasi Layanan Nomor Akses 1500218 PT KSP Sahabat Mitra Sejati | F9: Nomor Akses | G9: CRM 1 | H9: PGP | I9: 89000000 | J9: SME & GOV | K9: C | L9: Rahmatya Dwi Arini Rahadina | M9: 45302 | N9: 45328 | O9: Duta | P9: Done
A10: 9 | B10: P232407-05-00 | C10: 2024 | D10: Januari | E10: Sewa System Digital Contact Center Bank Jateng 2024-2025 | F10: CRM | G10: CRM 2 | H10: ARY | I10: 840000000 | J10: SME & GOV | K10: B | L10: Bagus Afiansah | M10: 45306 | N10: 45342 | O10: Gugum | P10: Done
A11: 10 | B11: P232479-01-00 | C11: 2024 | D11: Januari | E11: Novasi Layanan Nomor Akses 1500985 PT Sompo Insurance Indonesia | F11: Nomor Akses | G11: CRM 1 | H11: PGP | I11: 134000000 | J11: Private | K11: C | L11: Rahmatya Dwi Arini Rahadina | M11: 45308 | N11: 45442 | O11: Duta | P11: Done
A12: 11 | B12: P232343-07-00 | C12: 2024 | D12: Januari | E12: Pengembangan Layanan Voice Digital Asuransi Tokio Marine | F12: CRM | G12: CRM 1 | H12: PGP | I12: 51000000 | J12: Private | K12: C | L12: Bella Gusniri Ht | M12: 45309 | N12: 45349 | O12: Duta | P12: Done
A13: 12 | B13: P232400-02-00 | C13: 2024 | D13: Januari | E13: Perpanjangan Contact Center RS Sardjito dan Nomor Akses 1500705 2023-2024 | F13: CRM | G13: CRM 2 | H13: RGZ | I13: 279540000 | J13: SME & GOV | K13: B | L13: Bagus Afiansah | M13: 45310 | N13: 45342 | O13: Dwi | P13: Done
A14: 13 | B14: P232490-04-00 | C14: 2024 | D14: Januari | E14: Perpanjangan Pekerjaan Sewa Layanan Contact Center BMKG TA 2024 | F14: CRM | G14: CRM 2 | H14: RGZ | I14: 2275675676 | J14: SME & GOV | K14: B | L14: Angga Yudha Pratama | M14: 45315 | N14: 45352 | O14: Duta | P14: Done
A15: 14 | B15: P232120-01-00 | C15: 2024 | D15: Januari | E15: Nomor Akses MORATELINDO - 1500882 | F15: Nomor Akses | G15: CRM 1 | H15: PGP | I15: 2241600000 | J15: Private | K15: C | L15: Fadel Bahruraji | M15: 45317 | N15: 45352 | O15: Duta | P15: Done
A16: 15 | B16: P242580-02-00 | C16: 2024 | D16: Januari | E16: Perpanjangan Masking Outbound 14040 BSI 2023-2024 | F16: Nomor Akses | G16: CRM 2 | H16: IDR | I16: 136800000 | J16: SOE | K16: C | L16: Artha | M16: 45317 | N16: 45351 | O16: Dwi | P16: Done
A17: 16 | B17: P232075-06-00 | C17: 2024 | D17: Januari | E17: Layanan Contact Center Bank BJB Syariah 2023-2024 | F17: CRM | G17: CRM 1 | H17: RSA | I17: 1326306180 | J17: SME & GOV | K17: B | L17: Fuzi Ridwan Firdaus | M17: 45322 | N17: 45343 | O17: Duta | P17: Done
... A64: 63 | B64: P242925-01-00 | C64: 2024 | D64: April | E64: Sewa Layanan License Contact Center KSO Sucofindo Surveyor Indonesia | F64: CRM | G64: CRM 1 | H64: RZS | I64: 91168000 | J64: SOE | K64: C | L64: Yadi Nurcahyadi | M64: 45412 | N64: 45446 | O64: Duta | P64: Done
A65: 64 | B65: P232238-03-00 | C65: 2024 | D65: Mei | E65: Novasi Nomor Akses 1500852 Chubb Life Insurance Indonesia | F65: Nomor Akses | G65: CRM 2 | H65: PPP | I65: 112000000 | J65: Private | K65: C | L65: Yane Anastasia | M65: 45414 | N65: 45447 | O65: Duta | P65: cancel | U65: terkendala pr crossconnect di DCI (dari user tidak mau ada biaya tambahan)
A66: 65 | B66: P242857-03-00 | C66: 2024 | D66: Mei | E66: Layanan Contact Center 150511 Perumda Tirta Kanjuruhan Kabupaten Malang | F66: CRM | G66: CRM 2 | H66: RGZ | I66: 263452000 | J66: SME & GOV | K66: C | L66: Ricka Winatha | M66: 45415 | N66: 45443 | O66: Duta | P66: Done
A67: 66 | B67: P242585-03-00 | C67: 2024 | D67: Mei | E67: Perpanjangan Layanan Contact Center RSUD Tarakan Periode Jan - Des 2024 | F67: Nomor Akses | G67: CRM 2 | H67: RGZ | I67: 843600000 | J67: SME & GOV | K67: B | L67: Giany Nadlillah | M67: 45418 | N67: 45448 | O67: Gugum | P67: Done
A68: 67 | B68: P242711-06-00 | C68: 2024 | D68: Mei | E68: Nomor Akses 1500488 RS Hermina 2024 | F68: Nomor Akses | G68: CRM 1 | H68: RNO | I68: 361387200 | J68: Private | K68: C | L68: Fadel Bahruraji | M68: 45418 | N68: 45467 | O68: Gugum | P68: Done
A69: 68 | B69: P242795-03-00 | C69: 2024 | D69: Mei | E69: Penyediaan Nomor akses 1500988 PT Supra Primatama Nusantara 2024 | F69: Nomor Akses | G69: CRM 1 | H69: RNO | I69: 208460000 | J69: Private | K69: C | L69: Fadel Bahruraji | M69: 45418 | N69: 45448 | O69: Gugum | P69: Done
A70: 69 | B70: P242797-03-00 | C70: 2024 | D70: Mei | E70: Penyediaan Nomor akses 1500933 PT Supra Primatama Nusantara 2024 | F70: Nomor Akses | G70: CRM 1 | H70: RNO | I70: 208460000 | J70: Private | K70: C | L70: Fadel Bahruraji | M70: 45418 | N70: 45448 | O70: Gugum | P70: Done
A71: 70 | B71: P242769-02-00 | C71: 2024 | D71: Mei | E71: Layanan Call Center Bapenda Jabar Tahun 2024 | F71: CRM | G71: CRM 2 | H71: PGP | I71: 2354774775 | J71: SME & GOV | K71: B | L71: Chyntia Insani Dewi | M71: 45420 | N71: 45523 | O71: Duta | P71: Done
A72: 71 | B72: P242891-01-00 | C72: 2024 | D72: Mei | E72: (PNTL) Pekerjaan Pendukung Sales (Fulfillment) Periode April 2024 s/d Maret 2025 | F72: CRM | G72: CRM 2 | H72: EWI | I72: 37602672060 | J72: Telkom Group | K72: B | L72: Ipik Mimbo Busono | M72: 45422 | N72: 45469 | O72: Adi | P72: Done
A73: 72 | B73: P242912-01-00 | C73: 2024 | D73: Mei | E73: Layanan Call Center 14002 Bank Sumut April 2024 - Maret 2027 | F73: CRM | G73: CRM 2 | H73: RGZ | I73: 6150061800 | J73: SME & GOV | K73: B | L73: Kartika Alvianty Aziz | M73: 45425 | N73: 45457 | O73: Duta | P73: Done
A74: 73 | B74: P242916-00-00 | C74: 2024 | D74: Mei | E74: Masking Number Outbond PT Super Bank Indonesia 2024 | F74: Nomor Akses | G74: CRM 1 | H74: RSA | I74: 29000000 | J74: Private | K74: C | L74: Fadhli Fauzi | M74: 45425 | N74: 45443 | O74: Gugum | P74: Done
A75: 74 | B75: P242736-05-00 | C75: 2024 | D75: Mei | E75: [PNTL] SPGDT 119 Dinas Kesehatan Kota Bandung Tahun 2024 | F75: CRM | G75: CRM 1 | H75: YNR | I75: 1480840944 | J75: SME & GOV | K75: C | L75: Chyntia Insani Dewi | M75: 45426 | N75: 45447 | O75: Adi | P75: Done
A76: 75 | B76: P242824-01-00 | C76: 2024 | D76: Mei | E76: Layanan Halo BCA - Inbound Semarang | F76: CRM | G76: CRM 1 | H76: RZS | I76: 9277618000 | J76: Private | K76: C | L76: Ika Nursari | M76: 45430 | N76: 45446 | O76: Dwi | P76: Done
A77: 76 | B77: P242941-01-00 | C77: 2024 | D77: Mei | E77: Masking Number Nomor Akses 1500818 PT EKA MAS REPUBLIK (My Republik) | F77: Nomor Akses | G77: SSO | H77: FAH | I77: 21000000 | J77: Private | K77: C | L77: Fadel Bahruraji | M77: 45432 | N77: 45462 | O77: Gugum | P77: Done
... A95: 94 | B95: P242728-04-00 | C95: 2024 | D95: Juli | E95: Rebranding IVR Bank KB Bukopin | F95: CRM | G95: CRM 2 | H95: ARY | I95: 95000000 | J95: Private | K95: C | L95: Ika Nursari | M95: 45488 | N95: 45530 | O95: Dwi | P95: Done
A96: 95 | B96: P232477-06-00 | C96: 2024 | D96: Juli | E96: Novasi Nomor Akses 1500600 PizzaHut | F96: Nomor Akses | G96: SSO | H96: FAH | I96: 347120000 | J96: Private | K96: C | L96: Yane Anastasia | M96: 45490 | N96: 45520 | O96: Gugum | P96: cancel | U96: terkendala pr crossconnect di dc sigma
A97: 96 | B97: P243087-01-00 | C97: 2024 | D97: Juli | E97: Layanan Omnix dan Whatsapp Business BPD Kalimantan Selatan 2024-2025 | F97: CRM | G97: CRM 1 | H97: RZS | I97: 133600000 | J97: SME & GOV | K97: C | L97: Rachmat Hidayat | M97: 45496 | N97: 45537 | O97: Duta | P97: Done
A98: 97 | B98: P242993-04-00 | C98: 2024 | D98: Juli | E98: Penambahan Masking outbound & nomor akses 1500-654 PNM Tahap 1 | F98: Nomor Akses | G98: CRM 2 | H98: ARY | I98: 109400000 | J98: SOE | K98: C | L98: Rahmatya Dwi Arini Rahadina | M98: 45497 | N98: 45526 | O98: Gugum | P98: Done
A99: 98 | B99: P242904-03-00 | C99: 2024 | D99: Juli | E99: Penyediaan Layanan Call Center SPGDT 119 RSUD Aji Muhammad Parikesit Kab. Kukar 2024 | F99: CRM | G99: CRM 1 | H99: YNR | I99: 97000000 | J99: SME & GOV | K99: C | L99: Taufiq Abdurrahman Hanif | M99: 45498 | N99: 45530 | O99: Duta | P99: Done
A100: 99 | B100: P243122-02-00 | C100: 2024 | D100: Juli | E100: Nomor Akses 150-109 dan 1500-109 PT Patra Logistik | F100: Nomor Akses | G100: SSO | H100: FAH | I100: 202000000 | J100: SOE | K100: C | L100: Ibnu Pradipta | M100: 45502 | N100: 45532 | O100: Gugum | P100: Done
A101: 100 | B101: P242804-01-00 | C101: 2024 | D101: Juli | E101: Pengadaan Manage Operation Call Center Outbound PT Pesonna Optima Jasa Tahun 2024 | F101: Nomor Akses | G101: CRM 1 | H101: RSA | I101: 1052926126 | J101: SOE | K101: B | L101: Eko Winaryo | M101: 45503 | N101: 45553 | O101: Dwi | P101: Done
A102: 101 | B102: P242604-03-00 | C102: 2024 | D102: Agustus | E102: Sewa Nomor Akses Call Center dan Waba Dishub Kota Semarang 2024 | F102: CRM | G102: CRM 1 | H102: RZS | I102: 160480000 | J102: SME & GOV | K102: C | L102: Bagus Afiansah | M102: 45506 | N102: 45537 | O102: Duta | P102: Done
A103: 102 | B103: P243154-02-00 | C103: 2024 | D103: Agustus | E103: Masking Outbound 1500-111 & 1500-399 Bank Permata | F103: Nomor Akses | G103: CRM 1 | H103: RSA | I103: 228000000 | J103: Private | K103: C | L103: Fadhli Fauzi | M103: 45509 | N103: 45537 | O103: Gugum | P103: Done
...

Sheet List Order
A1: NO | B1: Periode | C1: Tahun | D1: Tanggal | E1: Order | F1: DASAR ORDER | G1: NO SURAT MODIN | H1: JENIS ORDER | I1: KLASIFIKASI ORDER | J1: PROVIDER | K1: AKHIR KONTRAK | L1: SISA KONTRAK | M1: NO ORDER | N1: SID 1 | O1: SID 2 | P1: IP Address | Q1: KETERANGAN | R1: STATUS | S1: Task | T1: harga | U1: NO BA | V1: TGL BA | W1: File BA
B2: September | C2: 2022 | D2: 44825 | E2: Permohonan percepatan aktivasi 150410 Layanan Bapenda JABAR | H2: Aktivasi | I2: Nomor Akses | J2: Telkom DWS | M2: 2-1789696190 | N2: 888337522249 | R2: Close | V2: 44827 | W2: file
B3: Juni | C3: 2023 | D3: 45090 | E3: Permohonan Aktivasi Astinet Dana di Site Infomedia | H3: Aktivasi | I3: Connectivity | J3: Telkom DWS | M3: 2-1994394079 | N3: 1758576065 | R3: Close | V3: 45111 | W3: file
B4: Juni | C4: 2023 | D4: 45097 | E4: Permohonan link backup metro dan backup internet Graha intan Jogya beda catuan odp | H4: Aktivasi | I4: Connectivity | J4: Telkom DWS | M4: 2-1996205782 | N4: 1761505393 | R4: Close | V4: 45117 | W4: file
B5: Juni | C5: 2023 | D5: 45097 | E5: Permohonan link backup metro dan backup internet Graha intan Jogya beda catuan odp | H5: Aktivasi | I5: Connectivity | J5: Telkom DWS | M5: 2-1996201116 | N5: 1758506619 | O5: 1761507764 | R5: Close | V5: 45117 | W5: file
B6: Juni | C6: 2023 | D6: 45103 | E6: Permohonan Aktivasi Astinet 1 Mbps Layanan Asabri | H6: Aktivasi | I6: Connectivity | J6: Telkom DWS | M6: 2-2002211739 | N6: 1763316563 | R6: Close | V6: 45120 | W6: file
B7: Juli | C7: 2023 | D7: 45110 | E7: Permohonan link Metro p2p 4 mbps interactive DC Infomedia Dan DC Cyber Apjii PT Persada Makmur Indonesia | H7: Aktivasi | I7: Connectivity | J7: Telkom DWS | M7: 2-2003014759 | N7: 1761375294 | O7: 1761162396 | R7: Close | V7: 45117 | W7: file
B8: Juli | C8: 2023 | D8: 45114 | E8: Permohonan Aktivasi Astinet 10 Mbps Layanan BJB | H8: Aktivasi | I8: Connectivity | J8: Telkom DWS | M8: 2-1994372762 | N8: 1758421735 | R8: Close | V8: 45100 | W8: file
B9: Juli | C9: 2023 | D9: 45117 | E9: Permohonan Novasi (Perubahan Nomor Translasi , Nomor Billing dan Channel Berlangganan) Nomor Akses 1500310 PT Zulu Alpha Papa (ZAP) | H9: Novasi | I9: Nomor Akses | J9: Telkom DWS | M9: 2-2006902048 | N9: 3700038-0028505709 | R9: Close | V9: 45121 | W9: file
B10: Desember | C10: 2023 | D10: 45278 | E10: Permohonan PSB Link Metro E Interaktif 2 Mbps dan Masking Outbound 1500989 PT Astra Honda Motor | F10: P232338-03-00 | H10: Aktivasi | I10: Connectivity | J10: Telkom DWS | M10: 2-2122341809 | N10: 1927800876 | O10: 1915062978 | R10: Close | V10: 45349 | W10: file
B11: Desember | C11: 2023 | D11: 45222 | E11: Permohonan PSB link Metro E BRI Ragunan To DC Infomedia Jatinegara | H11: Aktivasi | I11: Connectivity | J11: Telkom DWS | M11: 2-2075528687 | N11: 1787711454 | O11: 1788693609 | R11: Close | V11: 45222 | W11: file
B12: Desember | C12: 2023 | D12: 45267 | E12: Astinet Seamless Tendean | H12: Aktivasi | I12: Connectivity | J12: Telkom DWS | M12: 2-2106897759 | N12: 1883036085 | R12: Close | V12: 45267 | W12: file
A13: 7 | B13: Januari | C13: 2024 | D13: 45300 | E13: Aktivasi Nomor Akses 144 Layanan LKPP | F13: P232385-03-00 | G13: 00020/IN/INF2340122/24 | H13: Aktivasi | I13: Nomor Akses | J13: Telkom DWS | M13: 7000153184 | N13: 3700038-0028304160 | R13: Close | T13: 2500000 | U13: No 64 /YN 000/DR2–11220000/2024 | V13: 45293
A14: 10 | B14: Januari | C14: 2024 | D14: 45302 | E14: Aktivasi Nomor Akses 152 Layanan DJKI | F14: P232558-03-00 | G14: 00025/IN/INF2340122/24 | H14: Aktivasi | I14: Nomor Akses | J14: Telkom DWS | M14: 2-2129927421 | N14: 888389899665 | R14: Close | T14: 2500000 | U14: No: 807/YN 000/DR2–11220000/2024 | V14: 45324
A15: 25 | B15: Januari | C15: 2024 | D15: 45315 | E15: Aktivasi Masking Outbond 1500907 PT Affinity Health Indonesia | F15: P232267-03-00 | G15: 00054/IN/INF2340122/24 | H15: Aktivasi | I15: Nomor Akses | J15: Telkom DWS | M15: 2-2140073973 | N15: 888391471517 | R15: Close | T15: 580000 | U15: No: 812/YN 000/DR2–11220000/2024 | V15: 45324
A16: 30 | B16: Februari | C16: 2024 | D16: 45323 | E16: Aktivasi Nomor Akses 1500882 PT Mora Telematik Indonesia (MORATELINDO) | F16: P232120-01-00 | G16: 00068/IN/INF2340122/24 | H16: Aktivasi | I16: Nomor Akses | J16: Telkom DWS | M16: 2-2143307693 | N16: 888392001897 | R16: Close | T16: 2500000 | U16: No 1092 /YN 000/DR2–11220000/2024 | V16: 45327 | W16: file
A17: 33 | B17: Februari | C17: 2024 | D17: 45323 | E17: aktivasi Masking Nomor Akses 1500275 PT. Anugerah Pharmindo Lestari | F17: P232486-02-00 | G17: 00071/IN/INF2340122/24 | H17: Aktivasi | I17: Nomor Akses | J17: Telkom DWS | M17: 2-2143644304 | N17: 3700038-0029465223 | R17: Close | T17: 580000 | U17: No: 957/YN 000/DR2–11220000/2024 | V17: 45324
A18: 34 | B18: Februari | C18: 2024 | D18: 45323 | E18: Penambahan Nomor Masking Outbound Bank Syariah Indonesia | F18: P242580-02-00 | G18: 00073/IN/INF2340122/24 | H18: Aktivasi | I18: Nomor Akses | J18: Telkom DWS | M18: Masking : 2-2143315186 | N18: 3700038-45259 | R18: Close | T18: 580000 | U18: No 837/YN 000/DR2–11220000/2024 | V18: 45328
A19: 43 | B19: Februari | C19: 2024 | D19: 45341 | E19: Aktivasi Nomor Akses 1500019 Layanan RSIA Cikampek | F19: P232471-04-00 | G19: 00010/IN/INF2430233/24 | H19: Aktivasi | I19: Nomor Akses | J19: Telkom DWS | M19: 2-2149111663 | R19: Close | T19: 2500000 | U19: No 1167/YN 000/DR2–11220000/2024 | V19: 45343 | W19: file
A20: 45 | B20: Februari | C20: 2024 | D20: 45345 | E20: Aktivasi Nomor Akses 150707 Bank India | F20: P232266-01-00 | G20: 00017/IN/INF2430233/24 | H20: Aktivasi | I20: Nomor Akses | J20: Telkom DWS | M20: 2-2153037541 | N20: 888393977136 | R20: Close | T20: 2500000 | U20: No 1377/YN 000/DR2–11220000/2024 | V20: 45349 | W20: file
A21: 57 | B21: Maret | C21: 2024 | D21: 45365 | E21: Aktivasi Nomor Akses 1500211 Layanan BPRKS | F21: P242674-02-00 | G21: 00057/IN/INF2430233/24 | H21: Aktivasi | I21: Nomor Akses | J21: Telkom DWS | M21: 2-2161131461 | R21: Close | T21: 3080000 | W21: file
A22: 59 | B22: Maret | C22: 2024 | D22: 45369 | E22: Aktivasi Nomor Akses 1500598 Adhivasindo | F22: P242716-02-00 | G22: 00060/IN/INF2430233/24 | H22: Aktivasi | I22: Nomor Akses | J22: Telkom DWS | M22: 2-2163078394 | N22: 888396223561 | R22: Close | T22: 2500000 | V22: 45373 | W22: file
A23: 66 | B23: Maret | C23: 2024 | D23: 45376 | E23: aktivasi no akses inbound ,masking outbound 1500217 Layanan BRILIfe | F23: P242801–01-00 | G23: 00084/IN/INF2430233/24 | H23: Aktivasi | I23: Nomor Akses | J23: Telkom DWS | M23: 2-2166294501 | N23: 888396879847 | R23: Close | V23: 45378 | W23: file
B24: Maret | C24: 2024 | D24: 45377 | E24: Aktivasi metro bank fama | H24: Aktivasi | I24: Connectivity | J24: Telkom DWS | M24: 2-2166580141 | N24: 1931773524 | R24: Close | V24: 45377 | W24: file
A25: 88 | B25: Mei | C25: 2024 | D25: 45419 | E25: Aktivasi Nomor Akses 150511 Layanan Perumda Tirta Kanjuruhan Kab Malang | F25: P242857-03-00 | G25: 00131/IN/INF2430233/24 | H25: Aktivasi | I25: Nomor Akses | J25: Telkom DWS | M25: 2-2183638455 | R25: Close | U25: No 2087/YN 000/DR2–11220000/2024 | V25: 45425 | W25: file
A26: 92 | B26: Mei | C26: 2024 | D26: 45426 | E26: Masking Outbound Nomor Akses 1500333 Bank Fama (PT Super Bank Indonesia) | F26: P242916-00-00 | G26: 00139/IN/INF2430233/24 | H26: Aktivasi | I26: Nomor Akses | J26: Telkom DWS | M26: 2-2186074350 | Q26: 24CIN10F0046 - IO PT Super Bank Indonesia 2024 | R26: Close | U26: No 2134/YN 000/DR2–11220000/2024 | V26: 45429 | W26: file
A27: 97 | B27: Mei | C27: 2024 | D27: 45428 | E27: Aktivasi dan Masking Outbound Nomor Akses 1500063 PT Persada Makmur Indonesia | F27: 00147/IN/INF2430233/24 | G27: 00147/IN/INF2430233/24 | H27: Aktivasi | I27: Nomor Akses | J27: Telkom DWS | M27: 2-2186095404 | Q27: 24CIN10F0039 - IO CC 1500063 PT Persada Makmur Indonesia | R27: Close | U27: No: 2722/YN 000/DR2–11220000/2024 | V27: 45477 | W27: file
A28: 99 | B28: Mei | C28: 2024 | D28: 45433 | E28: Masking Outbound Nomor Akses 1500818 PT EKA MAS REPUBLIK (My Republik) | F28: P242941-01-00 | G28: 00154/IN/INF2430233/24 | H28: Aktivasi | I28: Nomor Akses | J28: Telkom DWS | M28: 2-2189531833 | Q28: 24CIN10F0049 - IO Masking Number No Akses 1500818 PT EKA MAS REPUBLIK | R28: Close | U28: No 2179/YN 000/DR2–11220000/2024 | V28: 45437 | W28: file
A29: 100 | B29: Mei | C29: 2024 | D29: 45433 | E29: Masking Outbound Nomor Akses 1500045 PT BNI Life Insurance | F29: P242791-02-00 | G29: 00156/IN/INF2430233/24 | H29: Aktivasi | I29: Nomor Akses | J29: Telkom DWS | M29: 2-2189528724 | Q29: 24CIN10F0041-IOCC1500045 PT BNI LIFE | R29: Close | U29: No 2181/YN 000/DR2–11220000/2024 | V29: 45437 | W29: file
A30: 112 | B30: Mei | C30: 2024 | D30: 45443 | E30: Aktivasi Nomor Akses 1500858 Nasmoco Semarang dan Nomor Akses 1500202 RSUP Dr Kariadi (Kariadi) | F30: 00003/M/INF24251/24 | G30: 00174/IN/INF2430233/24 | H30: Aktivasi | I30: Nomor Akses | J30: Telkom DWS | M30: 2-2194853153 | N30: 888272034303 | R30: Close | W30: file
B31: Mei | C31: 2024 | D31: 45443 | E31: Aktivasi Nomor Akses 1500858 Nasmoco Semarang dan Nomor Akses 1500202 RSUP Dr Kariadi (Nasmoco) | F31: 00003/M/INF24251/24 | G31: 00174/IN/INF2430233/24 | H31: Aktivasi | I31: Nomor Akses | J31: Telkom DWS | M31: 2-2194852752 | R31: Close
A32: 117 | B32: Juni | C32: 2024 | D32: 45453 | E32: Permohonan masking outbound 1500250 Layanan Dinas Telkom TENESA | F32: C.Tel.150/UM 000/SDA-D4050000/2024 | G32: 00182/IN/INF2430233/24 | H32: Aktivasi | I32: Nomor Akses | J32: Telkom DWS | M32: 2-2198168939 | N32: 888110631794 | R32: Close | W32: file
A33: 128 | B33: Juni | C33: 2024 | D33: 45457 | E33: Aktivasi Nomor Akses 1500910 PT Bank Hibank Indonesia | H33: Aktivasi | I33: Nomor Akses | J33: Telkom DWS | M33: 2-2200767238
A34: 144 | B34: Juli | C34: 2024 | D34: 45474 | E34: Aktivasi Nomor Akses 1500629 & Aktivasi Astinet PT HISI (Astinet) | F34: P242965-04-00 | G34: 00223/IN/INF2430233/24 | H34: Aktivasi | I34: Nomor Akses | J34: Telkom DWS | M34: 2-2208395513 | W34: file
A35: 149 | B35: Juli | C35: 2024 | D35: 45482 | E35: Permohonan Aktivasi Nomor Akses 1500699 & Masking Outbond 1500699 Mazuta Group | F35: P243026-04-00 | G35: 00235/IN/INF2430233/24 | H35: Aktivasi | I35: Nomor Akses | J35: Telkom DWS | M35: 2-2213657240 | N35: 888100956954 | R35: Close | W35: file
A36: 152 | B36: Juli | C36: 2024 | D36: 45488 | E36: Aktivasi Nomor Akses 150922 RS NGOERAH | F36: P242931-01-00 | G36: 00240/IN/INF2430233/24 | H36: Aktivasi | I36: Nomor Akses | J36: Telkom DWS | M36: 2-2217798861 | N36: 888151721386 | R36: Close | W36: file
A37: 166 | B37: Juli | C37: 2024 | D37: 30/07/2024 | E37: Masking Outbound Nomor Akses 1500654 PT. PERMODALAN NASIONAL MADANI | F37: P242993-04-00 | G37: 00264/IN/INF2430233/24 | H37: Aktivasi | I37: Nomor Akses | J37: Telkom DWS | M37: 2-2229514103
A38: 168 | B38: Juli | C38: 2024 | D38: 31/07/2024 | E38: PSB Link Metro E 8 Mbps dan Masking Outbound Nomor Akses 1500600 Pizza Hut (Masking) | F38: P232477-06-00 | G38: 00268/IN/INF2430233/24 | H38: Aktivasi | I38: Nomor Akses | J38: Telkom DWS | M38: 2-2231200333
A39: 169 | B39: Juli | C39: 2024 | D39: 31/07/2024 | E39: Masking Outbound Nomor Akses 1500569 PEGADAIAN | F39: P242804-01-00 | G39: 00270/IN/INF2430233/24 | H39: Aktivasi | I39: Nomor Akses | J39: Telkom DWS | M39: 2-2231219080
A40: 173 | B40: Agustus | C40: 2024 | D40: 45299 | E40: Aktivasi Nomor Akses 150109 dan 1500109 PT Patra Logistik | F40: P243122-02-00 | G40: 00275/M/INF2430233/24 | H40: Aktivasi | I40: Connectivity | J40: Telkom DWS
...

Sheet Sum 2024
AF1: Januari | AG1: Februari | AH1: Maret | AI1: April | AJ1: Mei | AK1: Juni | AL1: Juli | AM1: Agustus | AN1: September | AO1: Oktober | AP1: November | AQ1: Desember | AU1: 2024 | AV1: JANUARI | AX1: FEBRUARI | AZ1: MARET | BB1: APRIL | BD1: MAY | BF1: JUNI | BH1: JULI | BJ1: AGUSTUS | BL1: SEPTEMBER | BN1: OKTOBER | BP1: NOVEMBER | BR1: Desember
B2: Total Project | D2: =COUNTIFS('List Project'!C:C,"2024",'List Project'!P:P,"Done")+COUNTIFS('List Project'!C:C,"2024",'List Project'!P:P,"OGP") -> 150 | AE2: Revenue Project | AF2: =SUMIF('List Project'!D:D,"Januari",'List Project'!I:I) -> 1.5323832e+11 | AG2: =SUMIF('List Project'!D:D,"Februari",'List Project'!I:I) -> 1.0706982e+11 | AH2: =SUMIF('List Project'!D:D,"Maret",'List Project'!I:I) -> 158846645854 | AI2: =SUMIF('List Project'!D:D,"April",'List Project'!I:I) -> 21145067274 | AJ2: =SUMIF('List Project'!D:D,"Mei",'List Project'!I:I) -> 117613354628 | AK2: =SUMIF('List Project'!D:D,"Juni",'List Project'!I:I) -> 24387249911 | AL2: =SUMIF('List Project'!D:D,"Juli",'List Project'!I:I) -> 25193979370 | AM2: =SUMIF('List Project'!D:D,"Agustus",'List Project'!I:I) -> 95140991295 | AN2: =SUMIF('List Project'!D:D,"September",'List Project'!I:I) -> 1.3015875e+11 | AO2: =SUMIF('List Project'!D:D,"Oktober",'List Project'!I:I) -> 3.0147039e+11 | AP2: =SUMIF('List Project'!D:D,"November",'List Project'!I:I) -> 46006119761 | AQ2: =SUMIF('List Project'!D:D,"Desember",'List Project'!I:I) -> 1005993372947 | AR2: =SUM(AF2:AQ2) -> 2.1862641e+12 | AU2: Klasifikasi order | AV2: JUMLAH | AW2: TOTAL TAGIHAN | AX2: JUMLAH | AY2: TOTAL TAGIHAN | AZ2: JUMLAH | BA2: TOTAL TAGIHAN | BB2: JUMLAH | BC2: TOTAL TAGIHAN | BD2: JUMLAH | BE2: TOTAL TAGIHAN | BF2: JUMLAH | BG2: TOTAL TAGIHAN | BH2: JUMLAH | BI2: TOTAL TAGIHAN | BJ2: JUMLAH | BK2: TOTAL TAGIHAN | BL2: JUMLAH | BM2: TOTAL TAGIHAN | BN2: JUMLAH | BO2: TOTAL TAGIHAN | BP2: JUMLAH | BQ2: TOTAL TAGIHAN | BR2: JUMLAH | BS2: TOTAL TAGIHAN
AE3: Adi | AF3: =COUNTIFS('List Project'!D:D,"Januari",'List Project'!O:O,"Adi") -> 2 | AG3: =COUNTIFS('List Project'!D:D,"Februari",'List Project'!O:O,"Adi") -> 2 | AH3: =COUNTIFS('List Project'!D:D,"Maret",'List Project'!O:O,"Adi") -> 1 | AI3: =COUNTIFS('List Project'!D:D,"April",'List Project'!O:O,"Adi") -> 1 | AJ3: =COUNTIFS('List Project'!D:D,"Mei",'List Project'!O:O,"Adi") -> 2 | AK3: =COUNTIFS('List Project'!D:D,"Juni",'List Project'!O:O,"Adi") -> 0 | AL3: =COUNTIFS('List Project'!D:D,"Juli",'List Project'!O:O,"Adi") -> 0 | AM3: =COUNTIFS('List Project'!D:D,"Agustus",'List Project'!O:O,"Adi") -> 0 | AN3: =COUNTIFS('List Project'!D:D,"September",'List Project'!O:O,"Adi") -> 1 | AO3: =COUNTIFS('List Project'!D:D,"Oktober",'List Project'!O:O,"Adi") -> 2 | AP3: =COUNTIFS('List Project'!D:D,"November",'List Project'!O:O,"Adi") -> 1 | AQ3: =COUNTIFS('List Project'!D:D,"Desember",'List Project'!O:O,"Adi") -> 0 | AR3: =SUM(AF3:AQ3) -> 12 | AS3: =SUMIF('List Project'!O:O,"Adi",'List Project'!I:I) -> 124082524515 | AU3: NOMOR AKSES | AV3: =COUNTIFS('List Order'!B:B,"Januari",'List Order'!I:I,"Nomor Akses",'List Order'!C:C,"2024") -> 16 | AW3: =SUM(AW4:AW6) -> 21777500 | AX3: =COUNTIFS('List Order'!B:B,"Februari",'List Order'!I:I,"Nomor Akses",'List Order'!C:C,"2024") -> 10 | AY3: =SUM(AY4:AY6) -> 10160000 | AZ3: =COUNTIFS('List Order'!B:B,"Maret",'List Order'!I:I,"Nomor Akses",'List Order'!C:C,"2024") -> 7 | BA3: =SUM(BA4:BA6) -> 7080000 | BB3: =COUNTIFS('List Order'!B:B,"April",'List Order'!I:I,"Nomor Akses",'List Order'!C:C,"2024") -> 2 | BC3: =SUM(BC4:BC6) -> 1500000 | BD3: =COUNTIFS('List Order'!B:B,"Mei",'List Order'!I:I,"Nomor Akses",'List Order'!C:C,"2024") -> 19 | BE3: =SUM(BE4:BE6) -> 0 | BF3: =COUNTIFS('List Order'!B:B,"Juni",'List Order'!I:I,"Nomor Akses",'List Order'!C:C,"2024") -> 4 | BG3: =SUM(BG4:BG6) -> 0 | BH3: =COUNTIFS('List Order'!B:B,"Juli",'List Order'!I:I,"Nomor Akses",'List Order'!C:C,"2024") -> 23 | BI3: =SUM(BI4:BI6) -> 0 | BJ3: =COUNTIFS('List Order'!B:B,"Agustus",'List Order'!I:I,"Nomor Akses",'List Order'!C:C,"2024") -> 5 | BK3: =SUM(BK4:BK6) -> 0 | BL3: =COUNTIFS('List Order'!B:B,"September",'List Order'!I:I,"Nomor Akses",'List Order'!C:C,"2024") -> 8 | BM3: =SUM(BM4:BM6) -> 0 | BN3: =COUNTIFS('List Order'!B:B,"Oktober",'List Order'!I:I,"Nomor Akses",'List Order'!C:C,"2024") -> 12 | BO3: =SUM(BO4:BO6) -> 9240000 | BP3: =COUNTIFS('List Order'!B:B,"November",'List Order'!I:I,"Nomor Akses",'List Order'!C:C,"2024") -> 8 | BQ3: =SUM(BQ4:BQ6) -> 8078000 | BR3: =COUNTIFS('List Order'!B:B,"Desember",'List Order'!I:I,"Nomor Akses",'List Order'!C:C,"2024") -> 12 | BS3: =SUM(BS4:BS6) -> 6740000
B4: Total Revenue | D4: =SUMIF('List Project'!C:C,"2024",'List Project'!I:I) -> 407539404275 | AE4: Dwi | AF4: =COUNTIFS('List Project'!D:D,"Januari",'List Project'!O:O,"Dwi") -> 12 | AG4: =COUNTIFS('List Project'!D:D,"Februari",'List Project'!O:O,"Dwi") -> 12 | AH4: =COUNTIFS('List Project'!D:D,"Maret",'List Project'!O:O,"Dwi") -> 10 | AI4: =COUNTIFS('List Project'!D:D,"April",'List Project'!O:O,"Dwi") -> 7 | AJ4: =COUNTIFS('List Project'!D:D,"Mei",'List Project'!O:O,"Dwi") -> 4 | AK4: =COUNTIFS('List Project'!D:D,"Juni",'List Project'!O:O,"Dwi") -> 5 | AL4: =COUNTIFS('List Project'!D:D,"Juli",'List Project'!O:O,"Dwi") -> 9 | AM4: =COUNTIFS('List Project'!D:D,"Agustus",'List Project'!O:O,"Dwi") -> 4 | AN4: =COUNTIFS('List Project'!D:D,"September",'List Project'!O:O,"Dwi") -> 3 | AO4: =COUNTIFS('List Project'!D:D,"Oktober",'List Project'!O:O,"Dwi") -> 6 | AP4: =COUNTIFS('List Project'!D:D,"November",'List Project'!O:O,"Dwi") -> 9 | AQ4: =COUNTIFS('List Project'!D:D,"Desember",'List Project'!O:O,"Dwi") -> 4 | AR4: =SUM(AF4:AQ4) -> 85 | AS4: =SUMIF('List Project'!O:O,"Dwi",'List Project'!I:I) -> 4.398677e+11 | AU4: Aktivasi | AV4: =COUNTIFS('List Order'!C:C,"2024",'List Order'!B:B,"Januari",'List Order'!H:H,"Aktivasi",'List Order'!I:I,"Nomor Akses") -> 3 | AW4: =SUMIFS('List Order'!T:T,'List Order'!C:C,"2024",'List Order'!B:B,"Januari",'List Order'!H:H,"Aktivasi",'List Order'!I:I,"Nomor Akses") -> 5580000 | AX4: =COUNTIFS('List Order'!C:C,"2024",'List Order'!B:B,"Februari",'List Order'!H:H,"Aktivasi",'List Order'!I:I,"Nomor Akses") -> 6 | AY4: =SUMIFS('List Order'!T:T,'List Order'!C:C,"2024",'List Order'!B:B,"Februari",'List Order'!H:H,"Aktivasi",'List Order'!I:I,"Nomor Akses") -> 8660000 | AZ4: =COUNTIFS('List Order'!C:C,"2024",'List Order'!B:B,"Maret",'List Order'!H:H,"Aktivasi",'List Order'!I:I,"Nomor Akses") -> 3 | BA4: =SUMIFS('List Order'!T:T,'List Order'!C:C,"2024",'List Order'!B:B,"Maret",'List Order'!H:H,"Aktivasi",'List Order'!I:I,"Nomor Akses") -> 5580000 | BB4: =COUNTIFS('List Order'!C:C,"2024",'List Order'!B:B,"April",'List Order'!H:H,"Aktivasi",'List Order'!I:I,"Nomor Akses") -> 0 | BC4: =SUMIFS('List Order'!T:T,'List Order'!C:C,"2024",'List Order'!B:B,"April",'List Order'!H:H,"Aktivasi",'List Order'!I:I,"Nomor Akses") -> 0 | BD4: =COUNTIFS('List Order'!C:C,"2024",'List Order'!B:B,"Mei",'List Order'!H:H,"Aktivasi",'List Order'!I:I,"Nomor Akses") -> 7 | BE4: =SUMIFS('List Order'!T:T,'List Order'!C:C,"2024",'List Order'!B:B,"Mei",'List Order'!H:H,"Aktivasi",'List Order'!I:I,"Nomor Akses") -> 0 | BF4: =COUNTIFS('List Order'!C:C,"2024",'List Order'!B:B,"Juni",'List Order'!H:H,"Aktivasi",'List Order'!I:I,"Nomor Akses") -> 2 | BG4: =SUMIFS('List Order'!T:T,'List Order'!C:C,"2024",'List Order'!B:B,"Juni",'List Order'!H:H,"Aktivasi",'List Order'!I:I,"Nomor Akses") -> 0 | BH4: =COUNTIFS('List Order'!C:C,"2024",'List Order'!B:B,"Juli",'List Order'!H:H,"Aktivasi",'List Order'!I:I,"Nomor Akses") -> 18 | BI4: =SUMIFS('List Order'!T:T,'List Order'!C:C,"2024",'List Order'!B:B,"Juli",'List Order'!H:H,"Aktivasi",'List Order'!I:I,"Nomor Akses") -> 0 | BJ4: =COUNTIFS('List Order'!C:C,"2024",'List Order'!B:B,"Agustus",'List Order'!H:H,"Aktivasi",'List Order'!I:I,"Nomor Akses") -> 1 | BK4: =SUMIFS('List Order'!T:T,'List Order'!C:C,"2024",'List Order'!B:B,"Agustus",'List Order'!H:H,"Aktivasi",'List Order'!I:I,"Nomor Akses") -> 0 | BL4: =COUNTIFS('List Order'!C:C,"2024",'List Order'!B:B,"September",'List Order'!H:H,"Aktivasi",'List Order'!I:I,"Nomor Akses") -> 3 | BM4: =SUMIFS('List Order'!T:T,'List Order'!C:C,"2024",'List Order'!B:B,"September",'List Order'!H:H,"Aktivasi",'List Order'!I:I,"Nomor Akses") -> 0 | BN4: =COUNTIFS('List Order'!C:C,"2024",'List Order'!B:B,"Oktober",'List Order'!H:H,"Aktivasi",'List Order'!I:I,"Nomor Akses") -> 7 | BO4: =SUMIFS('List Order'!T:T,'List Order'!C:C,"2024",'List Order'!B:B,"Oktober",'List Order'!H:H,"Aktivasi",'List Order'!I:I,"Nomor Akses") -> 9240000 | BP4: =COUNTIFS('List Order'!C:C,"2024",'List Order'!B:B,"November",'List Order'!H:H,"Aktivasi",'List Order'!I:I,"Nomor Akses") -> 4 | BQ4: =SUMIFS('List Order'!T:T,'List Order'!C:C,"2024",'List Order'!B:B,"November",'List Order'!H:H,"Aktivasi",'List Order'!I:I,"Nomor Akses") -> 8078000 | BR4: =COUNTIFS('List Order'!C:C,"2024",'List Order'!B:B,"Desember",'List Order'!H:H,"Aktivasi",'List Order'!I:I,"Nomor Akses") -> 8 | BS4: =SUMIFS('List Order'!T:T,'List Order'!C:C,"2024",'List Order'!B:B,"Desember",'List Order'!H:H,"Aktivasi") -> 6740000
AE5: Duta | AF5: =COUNTIFS('List Project'!D:D,"Januari",'List Project'!O:O,"Duta") -> 26 | AG5: =COUNTIFS('List Project'!D:D,"Februari",'List Project'!O:O,"Duta") -> 14 | AH5: =COUNTIFS('List Project'!D:D,"Maret",'List Project'!O:O,"Duta") -> 11 | AI5: =COUNTIFS('List Project'!D:D,"April",'List Project'!O:O,"Duta") -> 8 | AJ5: =COUNTIFS('List Project'!D:D,"Mei",'List Project'!O:O,"Duta") -> 10 | AK5: =COUNTIFS('List Project'!D:D,"Juni",'List Project'!O:O,"Duta") -> 7 | AL5: =COUNTIFS('List Project'!D:D,"Juli",'List Project'!O:O,"Duta") -> 6 | AM5: =COUNTIFS('List Project'!D:D,"Agustus",'List Project'!O:O,"Duta") -> 12 | AN5: =COUNTIFS('List Project'!D:D,"September",'List Project'!O:O,"Duta") -> 5 | AO5: =COUNTIFS('List Project'!D:D,"Oktober",'List Project'!O:O,"Duta") -> 8 | AP5: =COUNTIFS('List Project'!D:D,"November",'List Project'!O:O,"Duta") -> 9 | AQ5: =COUNTIFS('List Project'!D:D,"Desember",'List Project'!O:O,"Duta") -> 5 | AR5: =SUM(AF5:AQ5) -> 121 | AS5: =SUMIF('List Project'!O:O,"Duta",'List Project'!I:I) -> 3.317266e+11 | AU5: Novasi | AV5: =COUNTIFS('List Order'!C:C,"2024",'List Order'!B:B,"Januari",'List Order'!H:H,"Novasi",'List Order'!I:I,"Nomor Akses") -> 8 | AW5: =SUMIFS('List Order'!T:T,'List Order'!C:C,"2024",'List Order'!B:B,"Januari",'List Order'!H:H,"Novasi",'List Order'!I:I,"Nomor Akses") -> 14697500 | AX5: =COUNTIFS('List Order'!C:C,"2024",'List Order'!B:B,"Februari",'List Order'!H:H,"Novasi",'List Order'!I:I,"Nomor Akses") -> 1 | AY5: =SUMIFS('List Order'!T:T,'List Order'!C:C,"2024",'List Order'!B:B,"Februari",'List Order'!H:H,"Novasi",'List Order'!I:I,"Nomor Akses") -> 1500000 | AZ5: =COUNTIFS('List Order'!C:C,"2024",'List Order'!B:B,"Maret",'List Order'!H:H,"Novasi",'List Order'!I:I,"Nomor Akses") -> 2 | BA5: =SUMIFS('List Order'!T:T,'List Order'!C:C,"2024",'List Order'!B:B,"Maret",'List Order'!H:H,"Novasi",'List Order'!I:I,"Nomor Akses") -> 1500000 | BB5: =COUNTIFS('List Order'!C:C,"2024",'List Order'!B:B,"April",'List Order'!H:H,"Novasi",'List Order'!I:I,"Nomor Akses") -> 1 | BC5: =SUMIFS('List Order'!T:T,'List Order'!C:C,"2024",'List Order'!B:B,"April",'List Order'!H:H,"Novasi",'List Order'!I:I,"Nomor Akses") -> 1500000 | BD5: =COUNTIFS('List Order'!C:C,"2024",'List Order'!B:B,"Mei",'List Order'!H:H,"Novasi",'List Order'!I:I,"Nomor Akses") -> 5 | BE5: =SUMIFS('List Order'!T:T,'List Order'!C:C,"2024",'List Order'!B:B,"Mei",'List Order'!H:H,"Novasi",'List Order'!I:I,"Nomor Akses") -> 0 | BF5: =COUNTIFS('List Order'!C:C,"2024",'List Order'!B:B,"Juni",'List Order'!H:H,"Novasi",'List Order'!I:I,"Nomor Akses") -> 0 | BG5: =SUMIFS('List Order'!T:T,'List Order'!C:C,"2024",'List Order'!B:B,"Juni",'List Order'!H:H,"Novasi",'List Order'!I:I,"Nomor Akses") -> 0 | BH5: =COUNTIFS('List Order'!C:C,"2024",'List Order'!B:B,"Juli",'List Order'!H:H,"Novasi",'List Order'!I:I,"Nomor Akses") -> 1 | BI5: =SUMIFS('List Order'!T:T,'List Order'!C:C,"2024",'List Order'!B:B,"Juli",'List Order'!H:H,"Novasi",'List Order'!I:I,"Nomor Akses") -> 0 | BJ5: =COUNTIFS('List Order'!C:C,"2024",'List Order'!B:B,"Agustus",'List Order'!H:H,"Novasi",'List Order'!I:I,"Nomor Akses") -> 2 | BK5: =SUMIFS('List Order'!T:T,'List Order'!C:C,"2024",'List Order'!B:B,"Agustus",'List Order'!H:H,"Novasi",'List Order'!I:I,"Nomor Akses") -> 0 | BL5: =COUNTIFS('List Order'!C:C,"2024",'List Order'!B:B,"September",'List Order'!H:H,"Novasi",'List Order'!I:I,"Nomor Akses") -> 1 | BM5: =SUMIFS('List Order'!T:T,'List Order'!C:C,"2024",'List Order'!B:B,"September",'List Order'!H:H,"Novasi",'List Order'!I:I,"Nomor Akses") -> 0 | BN5: =COUNTIFS('List Order'!C:C,"2024",'List Order'!B:B,"Oktober",'List Order'!H:H,"Novasi",'List Order'!I:I,"Nomor Akses") -> 1 | BO5: =SUMIFS('List Order'!T:T,'List Order'!C:C,"2024",'List Order'!B:B,"Oktober",'List Order'!H:H,"Novasi",'List Order'!I:I,"Nomor Akses") -> 0 | BP5: =COUNTIFS('List Order'!C:C,"2024",'List Order'!B:B,"November",'List Order'!H:H,"Novasi",'List Order'!I:I,"Nomor Akses") -> 0 | BQ5: =SUMIFS('List Order'!T:T,'List Order'!C:C,"2024",'List Order'!B:B,"November",'List Order'!H:H,"Novasi",'List Order'!I:I,"Nomor Akses") -> 0 | BR5: =COUNTIFS('List Order'!C:C,"2024",'List Order'!B:B,"Desember",'List Order'!H:H,"Novasi",'List Order'!I:I,"Nomor Akses") -> 1 | BS5: =SUMIFS('List Order'!T:T,'List Order'!C:C,"2024",'List Order'!B:B,"Desember",'List Order'!H:H,"Novasi") -> 0
AE6: Gugum | AF6: =COUNTIFS('List Project'!D:D,"Januari",'List Project'!O:O,"Gugum") -> 9 | AG6: =COUNTIFS('List Project'!D:D,"Februari",'List Project'!O:O,"Gugum") -> 6 | AH6: =COUNTIFS('List Project'!D:D,"Maret",'List Project'!O:O,"Gugum") -> 9 | AI6: =COUNTIFS('List Project'!D:D,"April",'List Project'!O:O,"Gugum") -> 5 | AJ6: =COUNTIFS('List Project'!D:D,"Mei",'List Project'!O:O,"Gugum") -> 11 | AK6: =COUNTIFS('List Project'!D:D,"Juni",'List Project'!O:O,"Gugum") -> 5 | AL6: =COUNTIFS('List Project'!D:D,"Juli",'List Project'!O:O,"Gugum") -> 20 | AM6: =COUNTIFS('List Project'!D:D,"Agustus",'List Project'!O:O,"Gugum") -> 10 | AN6: =COUNTIFS('List Project'!D:D,"September",'List Project'!O:O,"Gugum") -> 8 | AO6: =COUNTIFS('List Project'!D:D,"Oktober",'List Project'!O:O,"Gugum") -> 6 | AP6: =COUNTIFS('List Project'!D:D,"November",'List Project'!O:O,"Gugum") -> 1 | AQ6: =COUNTIFS('List Project'!D:D,"Desember",'List Project'!O:O,"Gugum") -> 7 | AR6: =SUM(AF6:AQ6) -> 97 | AS6: =SUMIF('List Project'!O:O,"Gugum",'List Project'!I:I) -> 1.2903765e+12 | AU6: Modified | AV6: =COUNTIFS('List Order'!C:C,"2024",'List Order'!B:B,"Januari",'List Order'!H:H,"Modified",'List Order'!I:I,"Nomor Akses") -> 1 | AW6: =SUMIFS('List Order'!T:T,'List Order'!C:C,"2024",'List Order'!B:B,"Januari",'List Order'!H:H,"Modified",'List Order'!I:I,"Nomor Akses") -> 1500000 | AX6: =COUNTIFS('List Order'!C:C,"2024",'List Order'!B:B,"Februari",'List Order'!H:H,"Modified",'List Order'!I:I,"Nomor Akses") -> 0 | AY6: =SUMIFS('List Order'!T:T,'List Order'!C:C,"2024",'List Order'!B:B,"Februari",'List Order'!H:H,"Modified",'List Order'!I:I,"Nomor Akses") -> 0 | AZ6: =COUNTIFS('List Order'!C:C,"2024",'List Order'!B:B,"Maret",'List Order'!H:H,"Modified",'List Order'!I:I,"Nomor Akses") -> 0 | BA6: =SUMIFS('List Order'!T:T,'List Order'!C:C,"2024",'List Order'!B:B,"Maret",'List Order'!H:H,"Modified",'List Order'!I:I,"Nomor Akses") -> 0 | BB6: =COUNTIFS('List Order'!C:C,"2024",'List Order'!B:B,"April",'List Order'!H:H,"Modified",'List Order'!I:I,"Nomor Akses") -> 0 | BC6: =SUMIFS('List Order'!T:T,'List Order'!C:C,"2024",'List Order'!B:B,"April",'List Order'!H:H,"Modified",'List Order'!I:I,"Nomor Akses") -> 0 | BD6: =COUNTIFS('List Order'!C:C,"2024",'List Order'!B:B,"Mei",'List Order'!H:H,"Modified",'List Order'!I:I,"Nomor Akses") -> 1 | BE6: =SUMIFS('List Order'!T:T,'List Order'!C:C,"2024",'List Order'!B:B,"Mei",'List Order'!H:H,"Modified",'List Order'!I:I,"Nomor Akses") -> 0 | BF6: =COUNTIFS('List Order'!C:C,"2024",'List Order'!B:B,"Juni",'List Order'!H:H,"Modified",'List Order'!I:I,"Nomor Akses") -> 1 | BG6: =SUMIFS('List Order'!T:T,'List Order'!C:C,"2024",'List Order'!B:B,"Juni",'List Order'!H:H,"Modified",'List Order'!I:I,"Nomor Akses") -> 0 | BH6: =COUNTIFS('List Order'!C:C,"2024",'List Order'!B:B,"Juni",'List Order'!H:H,"Modified",'List Order'!I:I,"Nomor Akses") -> 1 | BI6: =SUMIFS('List Order'!T:T,'List Order'!C:C,"2024",'List Order'!B:B,"Juli",'List Order'!H:H,"Modified",'List Order'!I:I,"Nomor Akses") -> 0 | BJ6: =COUNTIFS('List Order'!C:C,"2024",'List Order'!B:B,"Agustus",'List Order'!H:H,"Modified",'List Order'!I:I,"Nomor Akses") -> 0 | BK6: =SUMIFS('List Order'!T:T,'List Order'!C:C,"2024",'List Order'!B:B,"Agustus",'List Order'!H:H,"Modified",'List Order'!I:I,"Nomor Akses") -> 0 | BL6: =COUNTIFS('List Order'!C:C,"2024",'List Order'!B:B,"September",'List Order'!H:H,"Modified",'List Order'!I:I,"Nomor Akses") -> 0 | BM6: =SUMIFS('List Order'!T:T,'List Order'!C:C,"2024",'List Order'!B:B,"September",'List Order'!H:H,"Modified",'List Order'!I:I,"Nomor Akses") -> 0 | BN6: =COUNTIFS('List Order'!C:C,"2024",'List Order'!B:B,"Oktober",'List Order'!H:H,"Modified",'List Order'!I:I,"Nomor Akses") -> 2 | BO6: =SUMIFS('List Order'!T:T,'List Order'!C:C,"2024",'List Order'!B:B,"Oktober",'List Order'!H:H,"Modified",'List Order'!I:I,"Nomor Akses") -> 0 | BP6: =COUNTIFS('List Order'!C:C,"2024",'List Order'!B:B,"November",'List Order'!H:H,"Modified",'List Order'!I:I,"Nomor Akses") -> 0 | BQ6: =SUMIFS('List Order'!T:T,'List Order'!C:C,"2024",'List Order'!B:B,"November",'List Order'!H:H,"Modified",'List Order'!I:I,"Nomor Akses") -> 0 | BR6: =COUNTIFS('List Order'!C:C,"2024",'List Order'!B:B,"Desember",'List Order'!H:H,"Modified",'List Order'!I:I,"Nomor Akses") -> 0 | BS6: =SUMIFS('List Order'!T:T,'List Order'!C:C,"2024",'List Order'!B:B,"Desember",'List Order'!H:H,"Modified") -> 0
AE7: CRM Revenue | AF7: =SUMIFS('List Project'!I:I,'List Project'!D:D,"Januari",'List Project'!F:F,"CRM") -> 1.4836587e+11 | AG7: =SUMIFS('List Project'!I:I,'List Project'!D:D,"Februari",'List Project'!F:F,"CRM") -> 8.7567997e+10 | AH7: =SUMIFS('List Project'!I:I,'List Project'!D:D,"Maret",'List Project'!F:F,"CRM") -> 145799747591 | AI7: =SUMIFS('List Project'!I:I,'List Project'!D:D,"April",'List Project'!F:F,"CRM") -> 8682353274 | AJ7: =SUMIFS('List Project'!I:I,'List Project'!D:D,"Mei",'List Project'!F:F,"CRM") -> 113902049174 | AK7: =SUMIFS('List Project'!I:I,'List Project'!D:D,"Juni",'List Project'!F:F,"CRM") -> 23771281911 | AL7: =SUMIFS('List Project'!I:I,'List Project'!D:D,"Juli",'List Project'!F:F,"CRM") -> 21863193244 | AM7: =SUMIFS('List Project'!I:I,'List Project'!D:D,"Agustus",'List Project'!F:F,"CRM") -> 91198761295 | AN7: =SUMIFS('List Project'!I:I,'List Project'!D:D,"September",'List Project'!F:F,"CRM") -> 1.2913041e+11 | AO7: =SUMIFS('List Project'!I:I,'List Project'!D:D,"Oktober",'List Project'!F:F,"CRM") -> 3.0048593e+11 | AP7: =SUMIFS('List Project'!I:I,'List Project'!D:D,"November",'List Project'!F:F,"CRM") -> 44627615761 | AQ7: =SUMIFS('List Project'!I:I,'List Project'!D:D,"Desember",'List Project'!F:F,"CRM") -> 1005724372947 | AR7: =SUM(AF7:AQ7) -> 2.1211196e+12 | AU7: Dismentle | AV7: =COUNTIFS('List Order'!C:C,"2024",'List Order'!B:B,"Januari",'List Order'!H:H,"Dismantle",'List Order'!I:I,"Nomor Akses") -> 4 | AW7: =SUMIFS('List Order'!T:T,'List Order'!C:C,"2024",'List Order'!B:B,"Januari",'List Order'!H:H,"Dismantle",'List Order'!I:I,"Nomor Akses") -> 8000000 | AX7: =COUNTIFS('List Order'!C:C,"2024",'List Order'!B:B,"Februari",'List Order'!H:H,"Dismantle",'List Order'!I:I,"Nomor Akses") -> 3 | AY7: =SUMIFS('List Order'!T:T,'List Order'!C:C,"2024",'List Order'!B:B,"Februari",'List Order'!H:H,"Dismantle",'List Order'!I:I,"Nomor Akses") -> 4580000 | AZ7: =COUNTIFS('List Order'!C:C,"2024",'List Order'!B:B,"Maret",'List Order'!H:H,"Dismantle",'List Order'!I:I,"Nomor Akses") -> 2 | BA7: =SUMIFS('List Order'!T:T,'List Order'!C:C,"2024",'List Order'!B:B,"Maret",'List Order'!H:H,"Dismantle",'List Order'!I:I,"Nomor Akses") -> 4500000 | BB7: =COUNTIFS('List Order'!C:C,"2024",'List Order'!B:B,"April",'List Order'!H:H,"Dismantle",'List Order'!I:I,"Nomor Akses") -> 1 | BC7: =SUMIFS('List Order'!T:T,'List Order'!C:C,"2024",'List Order'!B:B,"April",'List Order'!H:H,"Dismantle",'List Order'!I:I,"Nomor Akses") -> 2325000 | BD7: =COUNTIFS('List Order'!C:C,"2024",'List Order'!B:B,"Mei",'List Order'!H:H,"Dismantle",'List Order'!I:I,"Nomor Akses") -> 6 | BE7: =SUMIFS('List Order'!T:T,'List Order'!C:C,"2024",'List Order'!B:B,"Mei",'List Order'!H:H,"Dismantle",'List Order'!I:I,"Nomor Akses") -> 9000000 | BF7: =COUNTIFS('List Order'!C:C,"2024",'List Order'!B:B,"Juni",'List Order'!H:H,"Dismantle",'List Order'!I:I,"Nomor Akses") -> 1 | BG7: =SUMIFS('List Order'!T:T,'List Order'!C:C,"2024",'List Order'!B:B,"Juni",'List Order'!H:H,"Dismantle",'List Order'!I:I,"Nomor Akses") -> 0 | BH7: =COUNTIFS('List Order'!C:C,"2024",'List Order'!B:B,"Juli",'List Order'!H:H,"Dismantle",'List Order'!I:I,"Nomor Akses") -> 4 | BI7: =SUMIFS('List Order'!T:T,'List Order'!C:C,"2024",'List Order'!B:B,"Juli",'List Order'!H:H,"Dismantle",'List Order'!I:I,"Nomor Akses") -> 0 | BJ7: =COUNTIFS('List Order'!C:C,"2024",'List Order'!B:B,"Agustus",'List Order'!H:H,"Dismantle",'List Order'!I:I,"Nomor Akses") -> 2 | BK7: =SUMIFS('List Order'!T:T,'List Order'!C:C,"2024",'List Order'!B:B,"Agustus",'List Order'!H:H,"Dismantle",'List Order'!I:I,"Nomor Akses") -> 0 | BL7: =COUNTIFS('List Order'!C:C,"2024",'List Order'!B:B,"September",'List Order'!H:H,"Dismantle",'List Order'!I:I,"Nomor Akses") -> 4 | BM7: =SUMIFS('List Order'!T:T,'List Order'!C:C,"2024",'List Order'!B:B,"September",'List Order'!H:H,"Dismantle",'List Order'!I:I,"Nomor Akses") -> 0 | BN7: =COUNTIFS('List Order'!C:C,"2024",'List Order'!B:B,"Oktober",'List Order'!H:H,"Dismantle",'List Order'!I:I,"Nomor Akses") -> 2 | BO7: =SUMIFS('List Order'!T:T,'List Order'!C:C,"2024",'List Order'!B:B,"Oktober",'List Order'!H:H,"Dismantle",'List Order'!I:I,"Nomor Akses") -> 29000000 | BP7: =COUNTIFS('List Order'!C:C,"2024",'List Order'!B:B,"November",'List Order'!H:H,"Dismantle",'List Order'!I:I,"Nomor Akses") -> 4 | BQ7: =SUMIFS('List Order'!T:T,'List Order'!C:C,"2024",'List Order'!B:B,"November",'List Order'!H:H,"Dismantle",'List Order'!I:I,"Nomor Akses") -> 3000000 | BR7: =COUNTIFS('List Order'!C:C,"2024",'List Order'!B:B,"Desember",'List Order'!H:H,"Dismantle",'List Order'!I:I,"Nomor Akses") -> 3 | BS7: =SUMIFS('List Order'!T:T,'List Order'!C:C,"2024",'List Order'!B:B,"Desember",'List Order'!H:H,"Dismantle") -> 1160000
AE8: SSO Revenue | AF8: =SUMIFS('List Project'!I:I,'List Project'!D:D,"Januari",'List Project'!F:F,"SSO") -> 0 | AG8: =SUMIFS('List Project'!I:I,'List Project'!D:D,"Februari",'List Project'!F:F,"SSO") -> 15923259005 | AH8: =SUMIFS('List Project'!I:I,'List Project'!D:D,"Maret",'List Project'!F:F,"SSO") -> 0 | AI8: =SUMIFS('List Project'!I:I,'List Project'!D:D,"April",'List Project'!F:F,"SSO") -> 0 | AJ8: =SUMIFS('List Project'!I:I,'List Project'!D:D,"Mei",'List Project'!F:F,"SSO") -> 0 | AK8: =SUMIFS('List Project'!I:I,'List Project'!D:D,"Juni",'List Project'!F:F,"SSO") -> 0 | AL8: =SUMIFS('List Project'!I:I,'List Project'!D:D,"Juli",'List Project'!F:F,"SSO") -> 0 | AM8: =SUMIFS('List Project'!I:I,'List Project'!D:D,"Agustus",'List Project'!F:F,"SSO") -> 0 | AN8: =SUMIFS('List Project'!I:I,'List Project'!D:D,"September",'List Project'!F:F,"SSO") -> 0 | AO8: =SUMIFS('List Project'!I:I,'List Project'!D:D,"Oktober",'List Project'!F:F,"SSO") -> 0 | AP8: =SUMIFS('List Project'!I:I,'List Project'!D:D,"November",'List Project'!F:F,"SSO") -> 0 | AQ8: =SUMIFS('List Project'!I:I,'List Project'!D:D,"Desember",'List Project'!F:F,"SSO") -> 0 | AR8: =SUM(AF8:AQ8) -> 15923259005 | AU8: CONNECTIVITY | AV8: =COUNTIFS('List Order'!B:B,"Januari",'List Order'!I:I,"Connectivity",'List Order'!C:C,"2024") -> 13 | AW8: =SUM(AW9:AW10) -> 78037527 | AX8: =COUNTIFS('List Order'!B:B,"Februari",'List Order'!I:I,"Connectivity",'List Order'!C:C,"2024") -> 15 | AY8: =SUM(AY9:AY10) -> 25330500 | AZ8: =COUNTIFS('List Order'!B:B,"Maret",'List Order'!I:I,"Connectivity",'List Order'!C:C,"2024") -> 14 | BA8: =SUM(BA9:BA10) -> 319788030 | BB8: =COUNTIFS('List Order'!B:B,"April",'List Order'!I:I,"Connectivity",'List Order'!C:C,"2024") -> 11 | BC8: =SUM(BC9:BC10) -> 138805130 | BD8: =COUNTIFS('List Order'!B:B,"Mei",'List Order'!I:I,"Connectivity",'List Order'!C:C,"2024") -> 14 | BE8: =SUM(BE9:BE10) -> 3993000 | BF8: =COUNTIFS('List Order'!B:B,"Juni",'List Order'!I:I,"Connectivity",'List Order'!C:C,"2024") -> 22 | BG8: =SUM(BG9:BG10) -> 0 | BH8: =COUNTIFS('List Order'!B:B,"Juli",'List Order'!I:I,"Connectivity",'List Order'!C:C,"2024") -> 41 | BI8: =SUM(BI9:BI10) -> 0 | BJ8: =COUNTIFS('List Order'!B:B,"Agustus",'List Order'!I:I,"Connectivity",'List Order'!C:C,"2024") -> 14 | BK8: =SUM(BK9:BK10) -> 0 | BL8: =COUNTIFS('List Order'!B:B,"September",'List Order'!I:I,"Connectivity",'List Order'!C:C,"2024") -> 7 | BM8: =SUM(BM9:BM10) -> 0 | BN8: =COUNTIFS('List Order'!B:B,"Oktober",'List Order'!I:I,"Connectivity",'List Order'!C:C,"2024") -> 14 | BO8: =SUM(BO9:BO10) -> 35345000 | BP8: =COUNTIFS('List Order'!B:B,"November",'List Order'!I:I,"Connectivity",'List Order'!C:C,"2024") -> 12 | BQ8: =SUM(BQ9:BQ10) -> 8811100 | BR8: =COUNTIFS('List Order'!B:B,"Desember",'List Order'!I:I,"Connectivity",'List Order'!C:C,"2024") -> 13 | BS8: =SUM(BS9:BS10) -> 24803400
AE9: Nomor Akses Revenue | AF9: =SUMIFS('List Project'!I:I,'List Project'!D:D,"Januari",'List Project'!F:F,"Nomor Akses") -> 4872456036 | AG9: =SUMIFS('List Project'!I:I,'List Project'!D:D,"Februari",'List Project'!F:F,"Nomor Akses") -> 3578559600 | AH9: =SUMIFS('List Project'!I:I,'List Project'!D:D,"Maret",'List Project'!F:F,"Nomor Akses") -> 13046898263 | AI9: =SUMIFS('List Project'!I:I,'List Project'!D:D,"April",'List Project'!F:F,"Nomor Akses") -> 12462714000 | AJ9: =SUMIFS('List Project'!I:I,'List Project'!D:D,"Mei",'List Project'!F:F,"Nomor Akses") -> 3711305454 | AK9: =SUMIFS('List Project'!I:I,'List Project'!D:D,"Juni",'List Project'!F:F,"Nomor Akses") -> 615968000 | AL9: =SUMIFS('List Project'!I:I,'List Project'!D:D,"Juli",'List Project'!F:F,"Nomor Akses") -> 3330786126 | AM9: =SUMIFS('List Project'!I:I,'List Project'!D:D,"Agustus",'List Project'!F:F,"Nomor Akses") -> 3942230000 | AN9: =SUMIFS('List Project'!I:I,'List Project'!D:D,"September",'List Project'!F:F,"Nomor Akses") -> 916340000 | AO9: =SUMIFS('List Project'!I:I,'List Project'!D:D,"Oktober",'List Project'!F:F,"Nomor Akses") -> 984468000 | AP9: =SUMIFS('List Project'!I:I,'List Project'!D:D,"November",'List Project'!F:F,"Nomor Akses") -> 1378504000 | AQ9: =SUMIFS('List Project'!I:I,'List Project'!D:D,"Desember",'List Project'!F:F,"Nomor Akses") -> 269000000 | AR9: =SUM(AF9:AQ9) -> 49109229479 | AU9: PSB | AV9: =COUNTIFS('List Order'!C:C,"2024",'List Order'!B:B,"Januari",'List Order'!H:H,"PSB",'List Order'!I:I,"Connectivity") -> 9 | AW9: =SUMIFS('List Order'!T:T,'List Order'!C:C,"2024",'List Order'!B:B,"Januari",'List Order'!H:H,"PSB",'List Order'!I:I,"Connectivity") -> 41652567 | AX9: =COUNTIFS('List Order'!C:C,"2024",'List Order'!B:B,"Februari",'List Order'!H:H,"PSB",'List Order'!I:I,"Connectivity") -> 7 | AY9: =SUMIFS('List Order'!T:T,'List Order'!C:C,"2024",'List Order'!B:B,"Februari",'List Order'!H:H,"PSB",'List Order'!I:I,"Connectivity") -> 13332500 | AZ9: =COUNTIFS('List Order'!C:C,"2024",'List Order'!B:B,"Maret",'List Order'!H:H,"PSB",'List Order'!I:I,"Connectivity") -> 4 | BA9: =SUMIFS('List Order'!T:T,'List Order'!C:C,"2024",'List Order'!B:B,"Maret",'List Order'!H:H,"PSB",'List Order'!I:I,"Connectivity") -> 9067000 | BB9: =COUNTIFS('List Order'!C:C,"2024",'List Order'!B:B,"April",'List Order'!H:H,"PSB",'List Order'!I:I,"Connectivity") -> 4 | BC9: =SUMIFS('List Order'!T:T,'List Order'!C:C,"2024",'List Order'!B:B,"April",'List Order'!H:H,"PSB",'List Order'!I:I,"Connectivity") -> 8327613 | BD9: =COUNTIFS('List Order'!C:C,"2024",'List Order'!B:B,"Mei",'List Order'!H:H,"PSB",'List Order'!I:I,"Connectivity") -> 6 | BE9: =SUMIFS('List Order'!T:T,'List Order'!C:C,"2024",'List Order'!B:B,"Mei",'List Order'!H:H,"PSB",'List Order'!I:I,"Connectivity") -> 3993000 | BF9: =COUNTIFS('List Order'!C:C,"2024",'List Order'!B:B,"Juni",'List Order'!H:H,"PSB",'List Order'!I:I,"Connectivity") -> 7 | BG9: =SUMIFS('List Order'!T:T,'List Order'!C:C,"2024",'List Order'!B:B,"Juni",'List Order'!H:H,"PSB",'List Order'!I:I,"Connectivity") -> 0 | BH9: =COUNTIFS('List Order'!C:C,"2024",'List Order'!B:B,"Juli",'List Order'!H:H,"PSB",'List Order'!I:I,"Connectivity") -> 12 | BI9: =SUMIFS('List Order'!T:T,'List Order'!C:C,"2024",'List Order'!B:B,"Juli",'List Order'!H:H,"PSB",'List Order'!I:I,"Connectivity") -> 0 | BJ9: =COUNTIFS('List Order'!C:C,"2024",'List Order'!B:B,"Agustus",'List Order'!H:H,"PSB",'List Order'!I:I,"Connectivity") -> 1 | BK9: =SUMIFS('List Order'!T:T,'List Order'!C:C,"2024",'List Order'!B:B,"Agustus",'List Order'!H:H,"PSB",'List Order'!I:I,"Connectivity") -> 0 | BL9: =COUNTIFS('List Order'!C:C,"2024",'List Order'!B:B,"September",'List Order'!H:H,"PSB",'List Order'!I:I,"Connectivity") -> 0 | BM9: =SUMIFS('List Order'!T:T,'List Order'!C:C,"2024",'List Order'!B:B,"September",'List Order'!H:H,"PSB",'List Order'!I:I,"Connectivity") -> 0 | BN9: =COUNTIFS('List Order'!C:C,"2024",'List Order'!B:B,"Oktober",'List Order'!H:H,"PSB",'List Order'!I:I,"Connectivity") -> 5 | BO9: =SUMIFS('List Order'!T:T,'List Order'!C:C,"2024",'List Order'!B:B,"Oktober",'List Order'!H:H,"PSB",'List Order'!I:I,"Connectivity") -> 35345000 | BP9: =COUNTIFS('List Order'!C:C,"2024",'List Order'!B:B,"November",'List Order'!H:H,"PSB",'List Order'!I:I,"Connectivity") -> 6 | BQ9: =SUMIFS('List Order'!T:T,'List Order'!C:C,"2024",'List Order'!B:B,"November",'List Order'!H:H,"PSB",'List Order'!I:I,"Connectivity") -> 5731100 | BR9: =COUNTIFS('List Order'!C:C,"2024",'List Order'!B:B,"Desember",'List Order'!H:H,"PSB",'List Order'!I:I,"Connectivity") -> 9 | BS9: =SUMIFS('List Order'!T:T,'List Order'!C:C,"2024",'List Order'!B:B,"Desember",'List Order'!H:H,"PSB",'List Order'!I:I,"Connectivity") -> 22196800
AU10: Upgrade | AV10: =COUNTIFS('List Order'!C:C,"2024",'List Order'!B:B,"Januari",'List Order'!H:H,"Upgrade",'List Order'!I:I,"Connectivity") -> 3 | AW10: =SUMIFS('List Order'!T:T,'List Order'!C:C,"2024",'List Order'!B:B,"Januari",'List Order'!H:H,"Upgrade",'List Order'!I:I,"Connectivity") -> 36384960 | AX10: =COUNTIFS('List Order'!C:C,"2024",'List Order'!B:B,"Februari",'List Order'!H:H,"Upgrade",'List Order'!I:I,"Connectivity") -> 3 | AY10: =SUMIFS('List Order'!T:T,'List Order'!C:C,"2024",'List Order'!B:B,"Februari",'List Order'!H:H,"Upgrade",'List Order'!I:I,"Connectivity") -> 11998000 | AZ10: =COUNTIFS('List Order'!C:C,"2024",'List Order'!B:B,"Maret",'List Order'!H:H,"Upgrade",'List Order'!I:I,"Connectivity") -> 5 | BA10: =SUMIFS('List Order'!T:T,'List Order'!C:C,"2024",'List Order'!B:B,"Maret",'List Order'!H:H,"Upgrade",'List Order'!I:I,"Connectivity") -> 310721030 | BB10: =COUNTIFS('List Order'!C:C,"2024",'List Order'!B:B,"April",'List Order'!H:H,"Upgrade",'List Order'!I:I,"Connectivity") -> 5 | BC10: =SUMIFS('List Order'!T:T,'List Order'!C:C,"2024",'List Order'!B:B,"April",'List Order'!H:H,"Upgrade",'List Order'!I:I,"Connectivity") -> 130477517 | BD10: =COUNTIFS('List Order'!C:C,"2024",'List Order'!B:B,"Mei",'List Order'!H:H,"Upgrade",'List Order'!I:I,"Connectivity") -> 3 | BE10: =SUMIFS('List Order'!T:T,'List Order'!C:C,"2024",'List Order'!B:B,"Mei",'List Order'!H:H,"Upgrade",'List Order'!I:I,"Connectivity") -> 0 | BF10: =COUNTIFS('List Order'!C:C,"2024",'List Order'!B:B,"Juni",'List Order'!H:H,"Upgrade",'List Order'!I:I,"Connectivity") -> 2 | BG10: =SUMIFS('List Order'!T:T,'List Order'!C:C,"2024",'List Order'!B:B,"Juni",'List Order'!H:H,"Upgrade",'List Order'!I:I,"Connectivity") -> 0 | BH10: =COUNTIFS('List Order'!C:C,"2024",'List Order'!B:B,"Juli",'List Order'!H:H,"Upgrade",'List Order'!I:I,"Connectivity") -> 0 | BI10: =SUMIFS('List Order'!T:T,'List Order'!C:C,"2024",'List Order'!B:B,"Juli",'List Order'!H:H,"Upgrade",'List Order'!I:I,"Connectivity") -> 0 | BJ10: =COUNTIFS('List Order'!C:C,"2024",'List Order'!B:B,"Agustus",'List Order'!H:H,"Upgrade",'List Order'!I:I,"Connectivity") -> 1 | BK10: =SUMIFS('List Order'!T:T,'List Order'!C:C,"2024",'List Order'!B:B,"Agustus",'List Order'!H:H,"Upgrade",'List Order'!I:I,"Connectivity") -> 0 | BL10: =COUNTIFS('List Order'!C:C,"2024",'List Order'!B:B,"September",'List Order'!H:H,"Upgrade",'List Order'!I:I,"Connectivity") -> 3 | BM10: =SUMIFS('List Order'!T:T,'List Order'!C:C,"2024",'List Order'!B:B,"September",'List Order'!H:H,"Upgrade",'List Order'!I:I,"Connectivity") -> 0 | BN10: =COUNTIFS('List Order'!C:C,"2024",'List Order'!B:B,"Oktober",'List Order'!H:H,"Upgrade",'List Order'!I:I,"Connectivity") -> 3 | BO10: =SUMIFS('List Order'!T:T,'List Order'!C:C,"2024",'List Order'!B:B,"Oktober",'List Order'!H:H,"Upgrade",'List Order'!I:I,"Connectivity") -> 0 | BP10: =COUNTIFS('List Order'!C:C,"2024",'List Order'!B:B,"November",'List Order'!H:H,"Upgrade",'List Order'!I:I,"Connectivity") -> 3 | BQ10: =SUMIFS('List Order'!T:T,'List Order'!C:C,"2024",'List Order'!B:B,"November",'List Order'!H:H,"Upgrade",'List Order'!I:I,"Connectivity") -> 3080000 | BR10: =COUNTIFS('List Order'!C:C,"2024",'List Order'!B:B,"Desember",'List Order'!H:H,"Upgrade",'List Order'!I:I,"Connectivity") -> 2 | BS10: =SUMIFS('List Order'!T:T,'List Order'!C:C,"2024",'List Order'!B:B,"Desember",'List Order'!H:H,"Upgrade",'List Order'!I:I,"Connectivity") -> 2606600
